/home/runner/workspace/query_data.py:2: LangChainDeprecationWarning: Importing Chroma from langchain.vectorstores is deprecated. Please replace deprecated imports:

>> from langchain.vectorstores import Chroma

with new imports of:

>> from langchain_community.vectorstores import Chroma
You can use the langchain cli to **automatically** upgrade many imports. Please see documentation here <https://python.langchain.com/docs/versions/v0_2/>
  from langchain.vectorstores.chroma import Chroma
/home/runner/workspace/query_data.py:33: LangChainDeprecationWarning: The class `Chroma` was deprecated in LangChain 0.2.9 and will be removed in 1.0. An updated version of the class exists in the :class:`~langchain-chroma package and should be used instead. To use it run `pip install -U :class:`~langchain-chroma` and import as `from :class:`~langchain_chroma import Chroma``.
  db = Chroma(persist_directory=CHROMA_PATH, embedding_function=embedding_function)
/home/runner/workspace/query_data.py:43: LangChainDeprecationWarning: The class `Ollama` was deprecated in LangChain 0.3.1 and will be removed in 1.0.0. An updated version of the class exists in the :class:`~langchain-ollama package and should be used instead. To use it run `pip install -U :class:`~langchain-ollama` and import as `from :class:`~langchain_ollama import OllamaLLM``.
  model = Ollama(base_url="http://0.0.0.0:1234", model="local")
Traceback (most recent call last):
  File "/home/runner/workspace/.pythonlibs/lib/python3.12/site-packages/urllib3/connection.py", line 198, in _new_conn
    sock = connection.create_connection(
           ^^^^^^^^^^^^^^^^^^^^^^^^^^^^^
  File "/home/runner/workspace/.pythonlibs/lib/python3.12/site-packages/urllib3/util/connection.py", line 85, in create_connection
    raise err
  File "/home/runner/workspace/.pythonlibs/lib/python3.12/site-packages/urllib3/util/connection.py", line 73, in create_connection
    sock.connect(sa)
ConnectionRefusedError: [Errno 111] Connection refused

The above exception was the direct cause of the following exception:

Traceback (most recent call last):
  File "/home/runner/workspace/.pythonlibs/lib/python3.12/site-packages/urllib3/connectionpool.py", line 787, in urlopen
    response = self._make_request(
               ^^^^^^^^^^^^^^^^^^^
  File "/home/runner/workspace/.pythonlibs/lib/python3.12/site-packages/urllib3/connectionpool.py", line 493, in _make_request
    conn.request(
  File "/home/runner/workspace/.pythonlibs/lib/python3.12/site-packages/urllib3/connection.py", line 445, in request
    self.endheaders()
  File "/nix/store/nb21sc3npfc8gvazwnrjxpvb5d48jysx-python3-3.12.7/lib/python3.12/http/client.py", line 1331, in endheaders
    self._send_output(message_body, encode_chunked=encode_chunked)
  File "/nix/store/nb21sc3npfc8gvazwnrjxpvb5d48jysx-python3-3.12.7/lib/python3.12/http/client.py", line 1091, in _send_output
    self.send(msg)
  File "/nix/store/nb21sc3npfc8gvazwnrjxpvb5d48jysx-python3-3.12.7/lib/python3.12/http/client.py", line 1035, in send
    self.connect()
  File "/home/runner/workspace/.pythonlibs/lib/python3.12/site-packages/urllib3/connection.py", line 276, in connect
    self.sock = self._new_conn()
                ^^^^^^^^^^^^^^^^
  File "/home/runner/workspace/.pythonlibs/lib/python3.12/site-packages/urllib3/connection.py", line 213, in _new_conn
    raise NewConnectionError(
urllib3.exceptions.NewConnectionError: <urllib3.connection.HTTPConnection object at 0x7f4d7a926e70>: Failed to establish a new connection: [Errno 111] Connection refused

The above exception was the direct cause of the following exception:

Traceback (most recent call last):
  File "/home/runner/workspace/.pythonlibs/lib/python3.12/site-packages/requests/adapters.py", line 667, in send
    resp = conn.urlopen(
           ^^^^^^^^^^^^^
  File "/home/runner/workspace/.pythonlibs/lib/python3.12/site-packages/urllib3/connectionpool.py", line 841, in urlopen
    retries = retries.increment(
              ^^^^^^^^^^^^^^^^^^
  File "/home/runner/workspace/.pythonlibs/lib/python3.12/site-packages/urllib3/util/retry.py", line 519, in increment
    raise MaxRetryError(_pool, url, reason) from reason  # type: ignore[arg-type]
    ^^^^^^^^^^^^^^^^^^^^^^^^^^^^^^^^^^^^^^^^^^^^^^^^^^^
urllib3.exceptions.MaxRetryError: HTTPConnectionPool(host='0.0.0.0', port=1234): Max retries exceeded with url: /api/generate (Caused by NewConnectionError('<urllib3.connection.HTTPConnection object at 0x7f4d7a926e70>: Failed to establish a new connection: [Errno 111] Connection refused'))

During handling of the above exception, another exception occurred:

Traceback (most recent call last):
  File "/home/runner/workspace/query_data.py", line 53, in <module>
    main()
  File "/home/runner/workspace/query_data.py", line 27, in main
    query_rag(query_text)
  File "/home/runner/workspace/query_data.py", line 44, in query_rag
    response_text = model.invoke(prompt)
                    ^^^^^^^^^^^^^^^^^^^^
  File "/home/runner/workspace/.pythonlibs/lib/python3.12/site-packages/langchain_core/language_models/llms.py", line 387, in invoke
    self.generate_prompt(
  File "/home/runner/workspace/.pythonlibs/lib/python3.12/site-packages/langchain_core/language_models/llms.py", line 760, in generate_prompt
    return self.generate(prompt_strings, stop=stop, callbacks=callbacks, **kwargs)
           ^^^^^^^^^^^^^^^^^^^^^^^^^^^^^^^^^^^^^^^^^^^^^^^^^^^^^^^^^^^^^^^^^^^^^^^
  File "/home/runner/workspace/.pythonlibs/lib/python3.12/site-packages/langchain_core/language_models/llms.py", line 963, in generate
    output = self._generate_helper(
             ^^^^^^^^^^^^^^^^^^^^^^
  File "/home/runner/workspace/.pythonlibs/lib/python3.12/site-packages/langchain_core/language_models/llms.py", line 784, in _generate_helper
    self._generate(
  File "/home/runner/workspace/.pythonlibs/lib/python3.12/site-packages/langchain_community/llms/ollama.py", line 437, in _generate
    final_chunk = super()._stream_with_aggregation(
                  ^^^^^^^^^^^^^^^^^^^^^^^^^^^^^^^^^
  File "/home/runner/workspace/.pythonlibs/lib/python3.12/site-packages/langchain_community/llms/ollama.py", line 349, in _stream_with_aggregation
    for stream_resp in self._create_generate_stream(prompt, stop, **kwargs):
                       ^^^^^^^^^^^^^^^^^^^^^^^^^^^^^^^^^^^^^^^^^^^^^^^^^^^^
  File "/home/runner/workspace/.pythonlibs/lib/python3.12/site-packages/langchain_community/llms/ollama.py", line 194, in _create_generate_stream
    yield from self._create_stream(
               ^^^^^^^^^^^^^^^^^^^^
  File "/home/runner/workspace/.pythonlibs/lib/python3.12/site-packages/langchain_community/llms/ollama.py", line 252, in _create_stream
    response = requests.post(
               ^^^^^^^^^^^^^^
  File "/home/runner/workspace/.pythonlibs/lib/python3.12/site-packages/requests/api.py", line 115, in post
    return request("post", url, data=data, json=json, **kwargs)
           ^^^^^^^^^^^^^^^^^^^^^^^^^^^^^^^^^^^^^^^^^^^^^^^^^^^^
  File "/home/runner/workspace/.pythonlibs/lib/python3.12/site-packages/requests/api.py", line 59, in request
    return session.request(method=method, url=url, **kwargs)
           ^^^^^^^^^^^^^^^^^^^^^^^^^^^^^^^^^^^^^^^^^^^^^^^^^
  File "/home/runner/workspace/.pythonlibs/lib/python3.12/site-packages/requests/sessions.py", line 589, in request
    resp = self.send(prep, **send_kwargs)
           ^^^^^^^^^^^^^^^^^^^^^^^^^^^^^^
  File "/home/runner/workspace/.pythonlibs/lib/python3.12/site-packages/requests/sessions.py", line 703, in send
    r = adapter.send(request, **kwargs)
        ^^^^^^^^^^^^^^^^^^^^^^^^^^^^^^^
  File "/home/runner/workspace/.pythonlibs/lib/python3.12/site-packages/requests/adapters.py", line 700, in send
    raise ConnectionError(e, request=request)