/home/runner/workspace/query_data.py:33: LangChainDeprecationWarning: The class `Chroma` was deprecated in LangChain 0.2.9 and will be removed in 1.0. An updated version of the class exists in the :class:`~langchain-chroma package and should be used instead. To use it run `pip install -U :class:`~langchain-chroma` and import as `from :class:`~langchain_chroma import Chroma``.
  db = Chroma(persist_directory=CHROMA_PATH, embedding_function=embedding_function)
/home/runner/workspace/query_data.py:43: LangChainDeprecationWarning: The class `OpenAI` was deprecated in LangChain 0.0.10 and will be removed in 1.0. An updated version of the class exists in the :class:`~langchain-openai package and should be used instead. To use it run `pip install -U :class:`~langchain-openai` and import as `from :class:`~langchain_openai import OpenAI``.
  model = OpenAI(
Traceback (most recent call last):
  File "/home/runner/workspace/.pythonlibs/lib/python3.12/site-packages/httpx/_transports/default.py", line 101, in map_httpcore_exceptions
    yield
  File "/home/runner/workspace/.pythonlibs/lib/python3.12/site-packages/httpx/_transports/default.py", line 250, in handle_request
    resp = self._pool.handle_request(req)
           ^^^^^^^^^^^^^^^^^^^^^^^^^^^^^^
  File "/home/runner/workspace/.pythonlibs/lib/python3.12/site-packages/httpcore/_sync/connection_pool.py", line 256, in handle_request
    raise exc from None
  File "/home/runner/workspace/.pythonlibs/lib/python3.12/site-packages/httpcore/_sync/connection_pool.py", line 236, in handle_request
    response = connection.handle_request(
               ^^^^^^^^^^^^^^^^^^^^^^^^^^
  File "/home/runner/workspace/.pythonlibs/lib/python3.12/site-packages/httpcore/_sync/connection.py", line 101, in handle_request
    raise exc
  File "/home/runner/workspace/.pythonlibs/lib/python3.12/site-packages/httpcore/_sync/connection.py", line 78, in handle_request
    stream = self._connect(request)
             ^^^^^^^^^^^^^^^^^^^^^^
  File "/home/runner/workspace/.pythonlibs/lib/python3.12/site-packages/httpcore/_sync/connection.py", line 124, in _connect
    stream = self._network_backend.connect_tcp(**kwargs)
             ^^^^^^^^^^^^^^^^^^^^^^^^^^^^^^^^^^^^^^^^^^^
  File "/home/runner/workspace/.pythonlibs/lib/python3.12/site-packages/httpcore/_backends/sync.py", line 207, in connect_tcp
    with map_exceptions(exc_map):
         ^^^^^^^^^^^^^^^^^^^^^^^
  File "/nix/store/nb21sc3npfc8gvazwnrjxpvb5d48jysx-python3-3.12.7/lib/python3.12/contextlib.py", line 158, in __exit__
    self.gen.throw(value)
  File "/home/runner/workspace/.pythonlibs/lib/python3.12/site-packages/httpcore/_exceptions.py", line 14, in map_exceptions
    raise to_exc(exc) from exc
httpcore.ConnectError: [Errno 111] Connection refused

The above exception was the direct cause of the following exception:

Traceback (most recent call last):
  File "/home/runner/workspace/.pythonlibs/lib/python3.12/site-packages/openai/_base_client.py", line 1003, in _request
    response = self._client.send(
               ^^^^^^^^^^^^^^^^^^
  File "/home/runner/workspace/.pythonlibs/lib/python3.12/site-packages/httpx/_client.py", line 914, in send
    response = self._send_handling_auth(
               ^^^^^^^^^^^^^^^^^^^^^^^^^
  File "/home/runner/workspace/.pythonlibs/lib/python3.12/site-packages/httpx/_client.py", line 942, in _send_handling_auth
    response = self._send_handling_redirects(
               ^^^^^^^^^^^^^^^^^^^^^^^^^^^^^^
  File "/home/runner/workspace/.pythonlibs/lib/python3.12/site-packages/httpx/_client.py", line 979, in _send_handling_redirects
    response = self._send_single_request(request)
               ^^^^^^^^^^^^^^^^^^^^^^^^^^^^^^^^^^
  File "/home/runner/workspace/.pythonlibs/lib/python3.12/site-packages/httpx/_client.py", line 1014, in _send_single_request
    response = transport.handle_request(request)
               ^^^^^^^^^^^^^^^^^^^^^^^^^^^^^^^^^
  File "/home/runner/workspace/.pythonlibs/lib/python3.12/site-packages/httpx/_transports/default.py", line 249, in handle_request
    with map_httpcore_exceptions():
         ^^^^^^^^^^^^^^^^^^^^^^^^^
  File "/nix/store/nb21sc3npfc8gvazwnrjxpvb5d48jysx-python3-3.12.7/lib/python3.12/contextlib.py", line 158, in __exit__
    self.gen.throw(value)
  File "/home/runner/workspace/.pythonlibs/lib/python3.12/site-packages/httpx/_transports/default.py", line 118, in map_httpcore_exceptions
    raise mapped_exc(message) from exc
httpx.ConnectError: [Errno 111] Connection refused

The above exception was the direct cause of the following exception:

Traceback (most recent call last):
  File "/home/runner/workspace/query_data.py", line 57, in <module>
    main()
  File "/home/runner/workspace/query_data.py", line 27, in main
    query_rag(query_text)
  File "/home/runner/workspace/query_data.py", line 48, in query_rag
    response_text = model.invoke(prompt)
                    ^^^^^^^^^^^^^^^^^^^^
  File "/home/runner/workspace/.pythonlibs/lib/python3.12/site-packages/langchain_core/language_models/llms.py", line 387, in invoke
    self.generate_prompt(
  File "/home/runner/workspace/.pythonlibs/lib/python3.12/site-packages/langchain_core/language_models/llms.py", line 760, in generate_prompt
    return self.generate(prompt_strings, stop=stop, callbacks=callbacks, **kwargs)
           ^^^^^^^^^^^^^^^^^^^^^^^^^^^^^^^^^^^^^^^^^^^^^^^^^^^^^^^^^^^^^^^^^^^^^^^
  File "/home/runner/workspace/.pythonlibs/lib/python3.12/site-packages/langchain_core/language_models/llms.py", line 963, in generate
    output = self._generate_helper(
             ^^^^^^^^^^^^^^^^^^^^^^
  File "/home/runner/workspace/.pythonlibs/lib/python3.12/site-packages/langchain_core/language_models/llms.py", line 784, in _generate_helper
    self._generate(
  File "/home/runner/workspace/.pythonlibs/lib/python3.12/site-packages/langchain_community/llms/openai.py", line 463, in _generate
    response = completion_with_retry(
               ^^^^^^^^^^^^^^^^^^^^^^
  File "/home/runner/workspace/.pythonlibs/lib/python3.12/site-packages/langchain_community/llms/openai.py", line 121, in completion_with_retry
    return llm.client.create(**kwargs)
           ^^^^^^^^^^^^^^^^^^^^^^^^^^^
  File "/home/runner/workspace/.pythonlibs/lib/python3.12/site-packages/openai/_utils/_utils.py", line 279, in wrapper
    return func(*args, **kwargs)
           ^^^^^^^^^^^^^^^^^^^^^
  File "/home/runner/workspace/.pythonlibs/lib/python3.12/site-packages/openai/resources/completions.py", line 539, in create
    return self._post(
           ^^^^^^^^^^^
  File "/home/runner/workspace/.pythonlibs/lib/python3.12/site-packages/openai/_base_client.py", line 1290, in post
    return cast(ResponseT, self.request(cast_to, opts, stream=stream, stream_cls=stream_cls))
                           ^^^^^^^^^^^^^^^^^^^^^^^^^^^^^^^^^^^^^^^^^^^^^^^^^^^^^^^^^^^^^^^^^
  File "/home/runner/workspace/.pythonlibs/lib/python3.12/site-packages/openai/_base_client.py", line 967, in request
    return self._request(
           ^^^^^^^^^^^^^^
  File "/home/runner/workspace/.pythonlibs/lib/python3.12/site-packages/openai/_base_client.py", line 1027, in _request
    return self._retry_request(
           ^^^^^^^^^^^^^^^^^^^^
  File "/home/runner/workspace/.pythonlibs/lib/python3.12/site-packages/openai/_base_client.py", line 1105, in _retry_request
    return self._request(
           ^^^^^^^^^^^^^^
  File "/home/runner/workspace/.pythonlibs/lib/python3.12/site-packages/openai/_base_client.py", line 1027, in _request
    return self._retry_request(
           ^^^^^^^^^^^^^^^^^^^^
  File "/home/runner/workspace/.pythonlibs/lib/python3.12/site-packages/openai/_base_client.py", line 1105, in _retry_request
    return self._request(
           ^^^^^^^^^^^^^^
  File "/home/runner/workspace/.pythonlibs/lib/python3.12/site-packages/openai/_base_client.py", line 1037, in _request
    raise APIConnectionError(request=request) from err
openai.APIConnectionError: Connection error.